{
    "registryname": "dragon's_blood_forge",
    "localizedname": "龙血锻造炉",
    "requires_blueprint": false,
    "color": "EE5E10",
    "failure-action": "still",
    "parts": [
        {
            "x": 0,
            "y": 0,
            "z": 0,
                        "elements": [
                "modularmachinery:blockcontroller@2"
            ]
        },
        {
            "x": -1,
            "y": 0,
            "z": 0,
                        "elements": [
                "item_fluid_energy_in/output"
            ]
        },
        {
            "x": 4,
            "y": 8,
            "z": 4,
            "elements": [
                "minecraft:purpur_block@0"
            ]
        },
        {
            "x": 2,
            "y": 4,
            "z": 2,
            "elements": [
                "iceandfire:dragon_bone_wall@0"
            ]
        },
        {
            "x": 1,
            "y": 0,
            "z": 0,
                        "elements": [
                "item_fluid_energy_in/output"
            ]
        },
        {
            "x": -2,
            "y": 0,
            "z": 0,
            "elements": [
                "minecraft:purpur_block@0"
            ]
        },
        {
            "x": -3,
            "y": 0,
            "z": 0,
            "elements": [
                "iceandfire:dragon_bone_wall@0"
            ]
        },
        {
            "x": 2,
            "y": 0,
            "z": 0,
            "elements": [
                "minecraft:purpur_block@0"
            ]
        },
        {
            "x": 3,
            "y": 0,
            "z": 0,
            "elements": [
                "iceandfire:dragon_bone_wall@0"
            ]
        },
        {
            "x": -6,
            "y": -2,
            "z": 15,
            "elements": [
                "contenttweaker:invar_casing@0"
            ]
        },
        {
            "x": -5,
            "y": -2,
            "z": 15,
            "elements": [
                "contenttweaker:invar_casing@0"
            ]
        },
        {
            "x": -2,
            "y": 2,
            "z": 17,
            "elements": [
                "minecraft:nether_brick_stairs@0"
            ]
        },
        {
            "x": -2,
            "y": -2,
            "z": 15,
            "elements": [
                "contenttweaker:bronze_firebox_casing@0"
            ]
        },
        {
            "x": -1,
            "y": -2,
            "z": 15,
            "elements": [
                "contenttweaker:invar_casing@0"
            ]
        },
        {
            "x": 0,
            "y": -2,
            "z": 15,
            "elements": [
                "contenttweaker:invar_casing@0"
            ]
        },
        {
            "x": 2,
            "y": 2,
            "z": 17,
            "elements": [
                "minecraft:nether_brick_stairs@1"
            ]
        },
        {
            "x": 1,
            "y": -2,
            "z": 15,
            "elements": [
                "contenttweaker:invar_casing@0"
            ]
        },
        {
            "x": 2,
            "y": -2,
            "z": 15,
            "elements": [
                "contenttweaker:bronze_firebox_casing@0"
            ]
        },
        {
            "x": 5,
            "y": -2,
            "z": 15,
            "elements": [
                "contenttweaker:invar_casing@0"
            ]
        },
        {
            "x": 6,
            "y": -2,
            "z": 15,
            "elements": [
                "contenttweaker:invar_casing@0"
            ]
        },
        {
            "x": -1,
            "y": 13,
            "z": 6,
            "elements": [
                "minecraft:stone_slab@6"
            ]
        },
        {
            "x": 0,
            "y": 13,
            "z": 6,
            "elements": [
                "minecraft:nether_brick@0"
            ]
        },
        {
            "x": 1,
            "y": 13,
            "z": 6,
            "elements": [
                "minecraft:stone_slab@6"
            ]
        },
        {
            "x": 4,
            "y": -1,
            "z": 0,
            "elements": [
                "minecraft:stone_slab@6"
            ]
        },
        {
            "x": 0,
            "y": 9,
            "z": 4,
            "elements": [
                "minecraft:nether_brick_stairs@2"
            ]
        },
        {
            "x": 3,
            "y": -1,
            "z": 0,
            "elements": [
                "thaumcraft:stone_eldritch_tile@0"
            ]
        },
        {
            "x": -2,
            "y": 5,
            "z": 2,
            "elements": [
                "minecraft:end_rod@1"
            ]
        },
        {
            "x": -3,
            "y": 1,
            "z": 0,
            "elements": [
                "minecraft:end_rod@1"
            ]
        },
        {
            "x": -1,
            "y": 5,
            "z": 2,
            "elements": [
                "minecraft:purpur_block@0"
            ]
        },
        {
            "x": 2,
            "y": -1,
            "z": 0,
            "elements": [
                "minecraft:purpur_block@0"
            ]
        },
        {
            "x": 1,
            "y": -1,
            "z": 0,
            "elements": [
                "minecraft:purpur_block@0"
            ]
        },
        {
            "x": -2,
            "y": 1,
            "z": 0,
            "elements": [
                "minecraft:purpur_block@0"
            ]
        },
        {
            "x": 0,
            "y": -1,
            "z": 0,
            "elements": [
                "minecraft:purpur_block@0"
            ]
        },
        {
            "x": -1,
            "y": 1,
            "z": 0,
                        "elements": [
                "item_fluid_energy_in/output"
            ]
        },
        {
            "x": 1,
            "y": 5,
            "z": 2,
            "elements": [
                "minecraft:purpur_block@0"
            ]
        },
        {
            "x": 2,
            "y": 5,
            "z": 2,
            "elements": [
                "minecraft:end_rod@1"
            ]
        },
        {
            "x": 0,
            "y": 1,
            "z": 0,
                        "elements": [
                "item_fluid_energy_in/output"
            ]
        },
        {
            "x": -1,
            "y": -1,
            "z": 0,
            "elements": [
                "minecraft:purpur_block@0"
            ]
        },
        {
            "x": 1,
            "y": 1,
            "z": 0,
                        "elements": [
                "item_fluid_energy_in/output"
            ]
        },
        {
            "x": -2,
            "y": -1,
            "z": 0,
            "elements": [
                "minecraft:purpur_block@0"
            ]
        },
        {
            "x": -3,
            "y": -1,
            "z": 0,
            "elements": [
                "thaumcraft:stone_eldritch_tile@0"
            ]
        },
        {
            "x": 2,
            "y": 1,
            "z": 0,
            "elements": [
                "minecraft:purpur_block@0"
            ]
        },
        {
            "x": 3,
            "y": 1,
            "z": 0,
            "elements": [
                "minecraft:end_rod@1"
            ]
        },
        {
            "x": -4,
            "y": -1,
            "z": 0,
            "elements": [
                "minecraft:stone_slab@6"
            ]
        },
        {
            "x": -6,
            "y": -1,
            "z": 15,
            "elements": [
                "minecraft:stone_slab@6"
            ]
        },
        {
            "x": -5,
            "y": -1,
            "z": 15,
            "elements": [
                "thaumcraft:stone_eldritch_tile@0"
            ]
        },
        {
            "x": -4,
            "y": -1,
            "z": 15,
            "elements": [
                "minecraft:nether_brick_stairs@3"
            ]
        },
        {
            "x": -3,
            "y": -1,
            "z": 15,
            "elements": [
                "thaumcraft:stone_eldritch_tile@0"
            ]
        },
        {
            "x": -1,
            "y": 3,
            "z": 17,
            "elements": [
                "minecraft:nether_brick_stairs@3"
            ]
        },
        {
            "x": -2,
            "y": -1,
            "z": 15,
            "elements": [
                "minecraft:purpur_block@0"
            ]
        },
        {
            "x": 1,
            "y": 3,
            "z": 17,
            "elements": [
                "minecraft:nether_brick_stairs@3"
            ]
        },
        {
            "x": 2,
            "y": -1,
            "z": 15,
            "elements": [
                "minecraft:purpur_block@0"
            ]
        },
        {
            "x": 3,
            "y": -1,
            "z": 15,
            "elements": [
                "thaumcraft:stone_eldritch_tile@0"
            ]
        },
        {
            "x": 4,
            "y": -1,
            "z": 15,
            "elements": [
                "minecraft:nether_brick_stairs@3"
            ]
        },
        {
            "x": 5,
            "y": -1,
            "z": 15,
            "elements": [
                "thaumcraft:stone_eldritch_tile@0"
            ]
        },
        {
            "x": 6,
            "y": -1,
            "z": 15,
            "elements": [
                "minecraft:stone_slab@6"
            ]
        },
        {
            "x": 4,
            "y": -2,
            "z": 0,
            "elements": [
                "contenttweaker:invar_casing@0"
            ]
        },
        {
            "x": 3,
            "y": -2,
            "z": 0,
            "elements": [
                "contenttweaker:invar_casing@0"
            ]
        },
        {
            "x": -1,
            "y": 6,
            "z": 2,
            "elements": [
                "thaumcraft:stone_eldritch_tile@0"
            ]
        },
        {
            "x": 2,
            "y": -2,
            "z": 0,
            "elements": [
                "contenttweaker:bronze_firebox_casing@0"
            ]
        },
        {
            "x": 0,
            "y": 6,
            "z": 2,
            "elements": [
                "minecraft:purpur_block@0"
            ]
        },
        {
            "x": 1,
            "y": -2,
            "z": 0,
            "elements": [
                "contenttweaker:invar_casing@0"
            ]
        },
        {
            "x": -2,
            "y": 2,
            "z": 0,
            "elements": [
                "minecraft:purpur_block@0"
            ]
        },
        {
            "x": 0,
            "y": -2,
            "z": 0,
            "elements": [
                "contenttweaker:invar_casing@0"
            ]
        },
        {
            "x": -1,
            "y": 2,
            "z": 0,
                        "elements": [
                "item_fluid_energy_in/output"
            ]
        },
        {
            "x": 1,
            "y": 6,
            "z": 2,
            "elements": [
                "thaumcraft:stone_eldritch_tile@0"
            ]
        },
        {
            "x": 0,
            "y": 2,
            "z": 0,
                        "elements": [
                "item_fluid_energy_in/output"
            ]
        },
        {
            "x": -1,
            "y": -2,
            "z": 0,
            "elements": [
                "contenttweaker:invar_casing@0"
            ]
        },
        {
            "x": 1,
            "y": 2,
            "z": 0,
                        "elements": [
                "item_fluid_energy_in/output"
            ]
        },
        {
            "x": -2,
            "y": -2,
            "z": 0,
            "elements": [
                "contenttweaker:bronze_firebox_casing@0"
            ]
        },
        {
            "x": -3,
            "y": -2,
            "z": 0,
            "elements": [
                "contenttweaker:invar_casing@0"
            ]
        },
        {
            "x": 2,
            "y": 2,
            "z": 0,
            "elements": [
                "minecraft:purpur_block@0"
            ]
        },
        {
            "x": -4,
            "y": -2,
            "z": 0,
            "elements": [
                "contenttweaker:invar_casing@0"
            ]
        },
        {
            "x": -5,
            "y": 0,
            "z": 15,
            "elements": [
                "iceandfire:dragon_bone_wall@0"
            ]
        },
        {
            "x": -3,
            "y": 0,
            "z": 15,
            "elements": [
                "thaumcraft:stone_eldritch_tile@0"
            ]
        },
        {
            "x": -1,
            "y": 4,
            "z": 17,
            "elements": [
                "minecraft:nether_brick_stairs@7"
            ]
        },
        {
            "x": -2,
            "y": 0,
            "z": 15,
            "elements": [
                "minecraft:purpur_block@0"
            ]
        },
        {
            "x": 1,
            "y": 4,
            "z": 17,
            "elements": [
                "minecraft:nether_brick_stairs@7"
            ]
        },
        {
            "x": 2,
            "y": 0,
            "z": 15,
            "elements": [
                "minecraft:purpur_block@0"
            ]
        },
        {
            "x": 3,
            "y": 0,
            "z": 15,
            "elements": [
                "thaumcraft:stone_eldritch_tile@0"
            ]
        },
        {
            "x": 5,
            "y": 0,
            "z": 15,
            "elements": [
                "iceandfire:dragon_bone_wall@0"
            ]
        },
        {
            "x": -1,
            "y": 7,
            "z": 2,
            "elements": [
                "iceandfire:dragon_bone_wall@0"
            ]
        },
        {
            "x": 0,
            "y": 7,
            "z": 2,
            "elements": [
                "minecraft:purpur_block@0"
            ]
        },
        {
            "x": -2,
            "y": 3,
            "z": 0,
            "elements": [
                "thaumcraft:stone_eldritch_tile@0"
            ]
        },
        {
            "x": -1,
            "y": 3,
            "z": 0,
            "elements": [
                "minecraft:purpur_block@0"
            ]
        },
        {
            "x": 1,
            "y": 7,
            "z": 2,
            "elements": [
                "iceandfire:dragon_bone_wall@0"
            ]
        },
        {
            "x": 0,
            "y": 3,
            "z": 0,
            "elements": [
                "minecraft:iron_bars@0"
            ]
        },
        {
            "x": 1,
            "y": 3,
            "z": 0,
            "elements": [
                "minecraft:purpur_block@0"
            ]
        },
        {
            "x": 2,
            "y": 3,
            "z": 0,
            "elements": [
                "thaumcraft:stone_eldritch_tile@0"
            ]
        },
        {
            "x": -5,
            "y": 1,
            "z": 15,
            "elements": [
                "minecraft:end_rod@1"
            ]
        },
        {
            "x": -3,
            "y": 1,
            "z": 15,
            "elements": [
                "iceandfire:dragon_bone_wall@0"
            ]
        },
        {
            "x": -1,
            "y": 5,
            "z": 17,
            "elements": [
                "minecraft:nether_brick_stairs@0"
            ]
        },
        {
            "x": -2,
            "y": 1,
            "z": 15,
            "elements": [
                "minecraft:purpur_block@0"
            ]
        },
        {
            "x": 1,
            "y": 5,
            "z": 17,
            "elements": [
                "minecraft:nether_brick_stairs@1"
            ]
        },
        {
            "x": 2,
            "y": 1,
            "z": 15,
            "elements": [
                "minecraft:purpur_block@0"
            ]
        },
        {
            "x": 3,
            "y": 1,
            "z": 15,
            "elements": [
                "iceandfire:dragon_bone_wall@0"
            ]
        },
        {
            "x": 5,
            "y": 1,
            "z": 15,
            "elements": [
                "minecraft:end_rod@1"
            ]
        },
        {
            "x": -1,
            "y": 8,
            "z": 2,
            "elements": [
                "minecraft:end_rod@1"
            ]
        },
        {
            "x": 0,
            "y": 8,
            "z": 2,
            "elements": [
                "minecraft:purpur_block@0"
            ]
        },
        {
            "x": -2,
            "y": 4,
            "z": 0,
            "elements": [
                "iceandfire:dragon_bone_wall@0"
            ]
        },
        {
            "x": -1,
            "y": 4,
            "z": 0,
            "elements": [
                "minecraft:purpur_block@0"
            ]
        },
        {
            "x": 1,
            "y": 8,
            "z": 2,
            "elements": [
                "minecraft:end_rod@1"
            ]
        },
        {
            "x": 0,
            "y": 4,
            "z": 0,
            "elements": [
                "minecraft:iron_bars@0"
            ]
        },
        {
            "x": 1,
            "y": 4,
            "z": 0,
            "elements": [
                "minecraft:purpur_block@0"
            ]
        },
        {
            "x": 2,
            "y": 4,
            "z": 0,
            "elements": [
                "iceandfire:dragon_bone_wall@0"
            ]
        },
        {
            "x": -7,
            "y": -2,
            "z": 13,
            "elements": [
                "contenttweaker:invar_casing@0"
            ]
        },
        {
            "x": -5,
            "y": -2,
            "z": 13,
            "elements": [
                "minecraft:purpur_block@0"
            ]
        },
        {
            "x": -3,
            "y": 2,
            "z": 15,
            "elements": [
                "minecraft:end_rod@1"
            ]
        },
        {
            "x": 0,
            "y": 6,
            "z": 17,
            "elements": [
                "minecraft:nether_brick_stairs@3"
            ]
        },
        {
            "x": -4,
            "y": -2,
            "z": 13,
            "elements": [
                "minecraft:lava@0"
            ]
        },
        {
            "x": -2,
            "y": 2,
            "z": 15,
            "elements": [
                "minecraft:purpur_block@0"
            ]
        },
        {
            "x": -3,
            "y": -2,
            "z": 13,
            "elements": [
                "contenttweaker:bronze_firebox_casing@0"
            ]
        },
        {
            "x": -2,
            "y": -2,
            "z": 13,
            "elements": [
                "contenttweaker:invar_casing@0"
            ]
        },
        {
            "x": -1,
            "y": -2,
            "z": 13,
            "elements": [
                "minecraft:lava@0"
            ]
        },
        {
            "x": 0,
            "y": -2,
            "z": 13,
            "elements": [
                "minecraft:lava@0"
            ]
        },
        {
            "x": 2,
            "y": 2,
            "z": 15,
            "elements": [
                "minecraft:purpur_block@0"
            ]
        },
        {
            "x": 3,
            "y": 2,
            "z": 15,
            "elements": [
                "minecraft:end_rod@1"
            ]
        },
        {
            "x": 1,
            "y": -2,
            "z": 13,
            "elements": [
                "minecraft:lava@0"
            ]
        },
        {
            "x": 2,
            "y": -2,
            "z": 13,
            "elements": [
                "contenttweaker:invar_casing@0"
            ]
        },
        {
            "x": 3,
            "y": -2,
            "z": 13,
            "elements": [
                "contenttweaker:bronze_firebox_casing@0"
            ]
        },
        {
            "x": 4,
            "y": -2,
            "z": 13,
            "elements": [
                "minecraft:lava@0"
            ]
        },
        {
            "x": 5,
            "y": -2,
            "z": 13,
            "elements": [
                "minecraft:purpur_block@0"
            ]
        },
        {
            "x": 7,
            "y": -2,
            "z": 13,
            "elements": [
                "contenttweaker:invar_casing@0"
            ]
        },
        {
            "x": 0,
            "y": 9,
            "z": 2,
            "elements": [
                "thaumcraft:stone_eldritch_tile@0"
            ]
        },
        {
            "x": -2,
            "y": 5,
            "z": 0,
            "elements": [
                "minecraft:end_rod@1"
            ]
        },
        {
            "x": -1,
            "y": 5,
            "z": 0,
            "elements": [
                "minecraft:purpur_block@0"
            ]
        },
        {
            "x": 0,
            "y": 5,
            "z": 0,
            "elements": [
                "minecraft:iron_bars@0"
            ]
        },
        {
            "x": 1,
            "y": 5,
            "z": 0,
            "elements": [
                "minecraft:purpur_block@0"
            ]
        },
        {
            "x": 2,
            "y": 5,
            "z": 0,
            "elements": [
                "minecraft:end_rod@1"
            ]
        },
        {
            "x": -7,
            "y": -1,
            "z": 13,
            "elements": [
                "thaumcraft:stone_eldritch_tile@0"
            ]
        },
        {
            "x": -6,
            "y": -1,
            "z": 13,
            "elements": [
                "thaumcraft:stone_eldritch_tile@0"
            ]
        },
        {
            "x": -5,
            "y": -1,
            "z": 13,
            "elements": [
                "minecraft:purpur_block@0"
            ]
        },
        {
            "x": 0,
            "y": 7,
            "z": 17,
            "elements": [
                "minecraft:nether_brick_stairs@7"
            ]
        },
        {
            "x": -2,
            "y": 3,
            "z": 15,
            "elements": [
                "minecraft:purpur_block@0"
            ]
        },
        {
            "x": -1,
            "y": 3,
            "z": 15,
            "elements": [
                "minecraft:purpur_block@0"
            ]
        },
        {
            "x": 1,
            "y": 3,
            "z": 15,
            "elements": [
                "minecraft:purpur_block@0"
            ]
        },
        {
            "x": 2,
            "y": 3,
            "z": 15,
            "elements": [
                "minecraft:purpur_block@0"
            ]
        },
        {
            "x": 5,
            "y": -1,
            "z": 13,
            "elements": [
                "minecraft:purpur_block@0"
            ]
        },
        {
            "x": 6,
            "y": -1,
            "z": 13,
            "elements": [
                "thaumcraft:stone_eldritch_tile@0"
            ]
        },
        {
            "x": 7,
            "y": -1,
            "z": 13,
            "elements": [
                "thaumcraft:stone_eldritch_tile@0"
            ]
        },
        {
            "x": 0,
            "y": 10,
            "z": 2,
            "elements": [
                "iceandfire:dragon_bone_wall@0"
            ]
        },
        {
            "x": -1,
            "y": 6,
            "z": 0,
            "elements": [
                "thaumcraft:stone_eldritch_tile@0"
            ]
        },
        {
            "x": 0,
            "y": 6,
            "z": 0,
            "elements": [
                "minecraft:purpur_block@0"
            ]
        },
        {
            "x": 1,
            "y": 6,
            "z": 0,
            "elements": [
                "thaumcraft:stone_eldritch_tile@0"
            ]
        },
        {
            "x": -7,
            "y": 0,
            "z": 13,
            "elements": [
                "iceandfire:dragon_bone_wall@0"
            ]
        },
        {
            "x": -6,
            "y": 0,
            "z": 13,
            "elements": [
                "thaumcraft:stone_eldritch_tile@0"
            ]
        },
        {
            "x": -5,
            "y": 0,
            "z": 13,
            "elements": [
                "minecraft:purpur_block@0"
            ]
        },
        {
            "x": 0,
            "y": 8,
            "z": 17,
            "elements": [
                "minecraft:nether_brick_stairs@2"
            ]
        },
        {
            "x": -2,
            "y": 4,
            "z": 15,
            "elements": [
                "minecraft:purpur_block@0"
            ]
        },
        {
            "x": -1,
            "y": 4,
            "z": 15,
            "elements": [
                "minecraft:purpur_block@0"
            ]
        },
        {
            "x": 1,
            "y": 4,
            "z": 15,
            "elements": [
                "minecraft:purpur_block@0"
            ]
        },
        {
            "x": 2,
            "y": 4,
            "z": 15,
            "elements": [
                "minecraft:purpur_block@0"
            ]
        },
        {
            "x": 5,
            "y": 0,
            "z": 13,
            "elements": [
                "minecraft:purpur_block@0"
            ]
        },
        {
            "x": 6,
            "y": 0,
            "z": 13,
            "elements": [
                "thaumcraft:stone_eldritch_tile@0"
            ]
        },
        {
            "x": 7,
            "y": 0,
            "z": 13,
            "elements": [
                "iceandfire:dragon_bone_wall@0"
            ]
        },
        {
            "x": 0,
            "y": 11,
            "z": 2,
            "elements": [
                "minecraft:end_rod@1"
            ]
        },
        {
            "x": -1,
            "y": 7,
            "z": 0,
            "elements": [
                "iceandfire:dragon_bone_wall@0"
            ]
        },
        {
            "x": 0,
            "y": 7,
            "z": 0,
            "elements": [
                "minecraft:purpur_block@0"
            ]
        },
        {
            "x": 1,
            "y": 7,
            "z": 0,
            "elements": [
                "iceandfire:dragon_bone_wall@0"
            ]
        },
        {
            "x": -7,
            "y": 1,
            "z": 13,
            "elements": [
                "minecraft:end_rod@1"
            ]
        },
        {
            "x": -6,
            "y": 1,
            "z": 13,
            "elements": [
                "iceandfire:dragon_bone_wall@0"
            ]
        },
        {
            "x": -5,
            "y": 1,
            "z": 13,
            "elements": [
                "minecraft:purpur_block@0"
            ]
        },
        {
            "x": -4,
            "y": 1,
            "z": 13,
            "elements": [
                "minecraft:purpur_block@0"
            ]
        },
        {
            "x": -2,
            "y": 5,
            "z": 15,
            "elements": [
                "minecraft:purpur_stairs@0"
            ]
        },
        {
            "x": -1,
            "y": 5,
            "z": 15,
            "elements": [
                "minecraft:purpur_block@0"
            ]
        },
        {
            "x": 1,
            "y": 5,
            "z": 15,
            "elements": [
                "minecraft:purpur_block@0"
            ]
        },
        {
            "x": 2,
            "y": 5,
            "z": 15,
            "elements": [
                "minecraft:purpur_stairs@1"
            ]
        },
        {
            "x": 4,
            "y": 1,
            "z": 13,
            "elements": [
                "minecraft:purpur_block@0"
            ]
        },
        {
            "x": 5,
            "y": 1,
            "z": 13,
            "elements": [
                "minecraft:purpur_block@0"
            ]
        },
        {
            "x": 6,
            "y": 1,
            "z": 13,
            "elements": [
                "iceandfire:dragon_bone_wall@0"
            ]
        },
        {
            "x": 7,
            "y": 1,
            "z": 13,
            "elements": [
                "minecraft:end_rod@1"
            ]
        },
        {
            "x": -1,
            "y": 8,
            "z": 0,
            "elements": [
                "minecraft:end_rod@1"
            ]
        },
        {
            "x": 0,
            "y": 8,
            "z": 0,
            "elements": [
                "minecraft:purpur_block@0"
            ]
        },
        {
            "x": 1,
            "y": 8,
            "z": 0,
            "elements": [
                "minecraft:end_rod@1"
            ]
        },
        {
            "x": -8,
            "y": -2,
            "z": 11,
            "elements": [
                "contenttweaker:invar_casing@0"
            ]
        },
        {
            "x": -6,
            "y": 2,
            "z": 13,
            "elements": [
                "minecraft:end_rod@1"
            ]
        },
        {
            "x": -5,
            "y": 2,
            "z": 13,
            "elements": [
                "minecraft:iron_bars@0"
            ]
        },
        {
            "x": -6,
            "y": -2,
            "z": 11,
            "elements": [
                "minecraft:purpur_block@0"
            ]
        },
        {
            "x": -4,
            "y": 2,
            "z": 13,
            "elements": [
                "minecraft:iron_bars@0"
            ]
        },
        {
            "x": -5,
            "y": -2,
            "z": 11,
            "elements": [
                "contenttweaker:bronze_firebox_casing@0"
            ]
        },
        {
            "x": -3,
            "y": 2,
            "z": 13,
            "elements": [
                "minecraft:purpur_block@0"
            ]
        },
        {
            "x": -1,
            "y": 6,
            "z": 15,
            "elements": [
                "minecraft:purpur_block@0"
            ]
        },
        {
            "x": 0,
            "y": 6,
            "z": 15,
            "elements": [
                "minecraft:purpur_block@0"
            ]
        },
        {
            "x": -4,
            "y": -2,
            "z": 11,
            "elements": [
                "contenttweaker:invar_casing@0"
            ]
        },
        {
            "x": -3,
            "y": -2,
            "z": 11,
            "elements": [
                "minecraft:lava@0"
            ]
        },
        {
            "x": 1,
            "y": 6,
            "z": 15,
            "elements": [
                "minecraft:purpur_block@0"
            ]
        },
        {
            "x": -2,
            "y": -2,
            "z": 11,
            "elements": [
                "minecraft:lava@0"
            ]
        },
        {
            "x": -1,
            "y": -2,
            "z": 11,
            "elements": [
                "minecraft:lava@0"
            ]
        },
        {
            "x": 0,
            "y": -2,
            "z": 11,
            "elements": [
                "minecraft:lava@0"
            ]
        },
        {
            "x": 3,
            "y": 2,
            "z": 13,
            "elements": [
                "minecraft:purpur_block@0"
            ]
        },
        {
            "x": 1,
            "y": -2,
            "z": 11,
            "elements": [
                "minecraft:lava@0"
            ]
        },
        {
            "x": 4,
            "y": 2,
            "z": 13,
            "elements": [
                "minecraft:iron_bars@0"
            ]
        },
        {
            "x": 2,
            "y": -2,
            "z": 11,
            "elements": [
                "minecraft:lava@0"
            ]
        },
        {
            "x": 5,
            "y": 2,
            "z": 13,
            "elements": [
                "minecraft:iron_bars@0"
            ]
        },
        {
            "x": 3,
            "y": -2,
            "z": 11,
            "elements": [
                "minecraft:lava@0"
            ]
        },
        {
            "x": 6,
            "y": 2,
            "z": 13,
            "elements": [
                "minecraft:end_rod@1"
            ]
        },
        {
            "x": 4,
            "y": -2,
            "z": 11,
            "elements": [
                "contenttweaker:invar_casing@0"
            ]
        },
        {
            "x": 5,
            "y": -2,
            "z": 11,
            "elements": [
                "contenttweaker:bronze_firebox_casing@0"
            ]
        },
        {
            "x": 6,
            "y": -2,
            "z": 11,
            "elements": [
                "minecraft:purpur_block@0"
            ]
        },
        {
            "x": 8,
            "y": -2,
            "z": 11,
            "elements": [
                "contenttweaker:invar_casing@0"
            ]
        },
        {
            "x": 0,
            "y": 9,
            "z": 0,
            "elements": [
                "thaumcraft:stone_eldritch_tile@0"
            ]
        },
        {
            "x": -8,
            "y": -1,
            "z": 11,
            "elements": [
                "thaumcraft:stone_eldritch_tile@0"
            ]
        },
        {
            "x": -7,
            "y": -1,
            "z": 11,
            "elements": [
                "thaumcraft:stone_eldritch_tile@0"
            ]
        },
        {
            "x": -5,
            "y": 3,
            "z": 13,
            "elements": [
                "minecraft:iron_bars@0"
            ]
        },
        {
            "x": -6,
            "y": -1,
            "z": 11,
            "elements": [
                "minecraft:purpur_block@0"
            ]
        },
        {
            "x": -4,
            "y": 3,
            "z": 13,
            "elements": [
                "minecraft:iron_bars@0"
            ]
        },
        {
            "x": -3,
            "y": 3,
            "z": 13,
            "elements": [
                "minecraft:nether_brick@0"
            ]
        },
        {
            "x": -1,
            "y": 7,
            "z": 15,
            "elements": [
                "minecraft:purpur_block@0"
            ]
        },
        {
            "x": 0,
            "y": 7,
            "z": 15,
            "elements": [
                "minecraft:purpur_block@0"
            ]
        },
        {
            "x": -2,
            "y": 3,
            "z": 13,
            "elements": [
                "minecraft:purpur_block@0"
            ]
        },
        {
            "x": -1,
            "y": 3,
            "z": 13,
            "elements": [
                "minecraft:purpur_block@0"
            ]
        },
        {
            "x": 1,
            "y": 7,
            "z": 15,
            "elements": [
                "minecraft:purpur_block@0"
            ]
        },
        {
            "x": 1,
            "y": 3,
            "z": 13,
            "elements": [
                "minecraft:purpur_block@0"
            ]
        },
        {
            "x": 2,
            "y": 3,
            "z": 13,
            "elements": [
                "minecraft:purpur_block@0"
            ]
        },
        {
            "x": 3,
            "y": 3,
            "z": 13,
            "elements": [
                "minecraft:nether_brick@0"
            ]
        },
        {
            "x": 4,
            "y": 3,
            "z": 13,
            "elements": [
                "minecraft:iron_bars@0"
            ]
        },
        {
            "x": 5,
            "y": 3,
            "z": 13,
            "elements": [
                "minecraft:iron_bars@0"
            ]
        },
        {
            "x": 6,
            "y": -1,
            "z": 11,
            "elements": [
                "minecraft:purpur_block@0"
            ]
        },
        {
            "x": 7,
            "y": -1,
            "z": 11,
            "elements": [
                "thaumcraft:stone_eldritch_tile@0"
            ]
        },
        {
            "x": 8,
            "y": -1,
            "z": 11,
            "elements": [
                "thaumcraft:stone_eldritch_tile@0"
            ]
        },
        {
            "x": 0,
            "y": 10,
            "z": 0,
            "elements": [
                "iceandfire:dragon_bone_wall@0"
            ]
        },
        {
            "x": -8,
            "y": 0,
            "z": 11,
            "elements": [
                "iceandfire:dragon_bone_wall@0"
            ]
        },
        {
            "x": -7,
            "y": 0,
            "z": 11,
            "elements": [
                "thaumcraft:stone_eldritch_tile@0"
            ]
        },
        {
            "x": -6,
            "y": 0,
            "z": 11,
            "elements": [
                "minecraft:purpur_block@0"
            ]
        },
        {
            "x": -4,
            "y": 4,
            "z": 13,
            "elements": [
                "minecraft:stone_slab@6"
            ]
        },
        {
            "x": -3,
            "y": 4,
            "z": 13,
            "elements": [
                "minecraft:nether_brick@0"
            ]
        },
        {
            "x": -1,
            "y": 8,
            "z": 15,
            "elements": [
                "minecraft:purpur_block@0"
            ]
        },
        {
            "x": 0,
            "y": 8,
            "z": 15,
            "elements": [
                "minecraft:purpur_block@0"
            ]
        },
        {
            "x": -1,
            "y": 4,
            "z": 13,
            "elements": [
                "minecraft:purpur_block@0"
            ]
        },
        {
            "x": 1,
            "y": 8,
            "z": 15,
            "elements": [
                "minecraft:purpur_block@0"
            ]
        },
        {
            "x": 1,
            "y": 4,
            "z": 13,
            "elements": [
                "minecraft:purpur_block@0"
            ]
        },
        {
            "x": 3,
            "y": 4,
            "z": 13,
            "elements": [
                "minecraft:nether_brick@0"
            ]
        },
        {
            "x": 4,
            "y": 4,
            "z": 13,
            "elements": [
                "minecraft:stone_slab@6"
            ]
        },
        {
            "x": 6,
            "y": 0,
            "z": 11,
            "elements": [
                "minecraft:purpur_block@0"
            ]
        },
        {
            "x": 7,
            "y": 0,
            "z": 11,
            "elements": [
                "thaumcraft:stone_eldritch_tile@0"
            ]
        },
        {
            "x": 8,
            "y": 0,
            "z": 11,
            "elements": [
                "iceandfire:dragon_bone_wall@0"
            ]
        },
        {
            "x": 0,
            "y": 11,
            "z": 0,
            "elements": [
                "minecraft:end_rod@1"
            ]
        },
        {
            "x": -8,
            "y": 1,
            "z": 11,
            "elements": [
                "minecraft:end_rod@1"
            ]
        },
        {
            "x": -7,
            "y": 1,
            "z": 11,
            "elements": [
                "iceandfire:dragon_bone_wall@0"
            ]
        },
        {
            "x": -6,
            "y": 1,
            "z": 11,
            "elements": [
                "minecraft:purpur_block@0"
            ]
        },
        {
            "x": -3,
            "y": 5,
            "z": 13,
            "elements": [
                "minecraft:nether_brick@0"
            ]
        },
        {
            "x": -1,
            "y": 5,
            "z": 13,
            "elements": [
                "minecraft:purpur_block@0"
            ]
        },
        {
            "x": 1,
            "y": 5,
            "z": 13,
            "elements": [
                "minecraft:purpur_block@0"
            ]
        },
        {
            "x": 3,
            "y": 5,
            "z": 13,
            "elements": [
                "minecraft:nether_brick@0"
            ]
        },
        {
            "x": 6,
            "y": 1,
            "z": 11,
            "elements": [
                "minecraft:purpur_block@0"
            ]
        },
        {
            "x": 7,
            "y": 1,
            "z": 11,
            "elements": [
                "iceandfire:dragon_bone_wall@0"
            ]
        },
        {
            "x": 8,
            "y": 1,
            "z": 11,
            "elements": [
                "minecraft:end_rod@1"
            ]
        },
        {
            "x": -7,
            "y": 2,
            "z": 11,
            "elements": [
                "minecraft:end_rod@1"
            ]
        },
        {
            "x": -8,
            "y": -2,
            "z": 9,
            "elements": [
                "contenttweaker:invar_casing@0"
            ]
        },
        {
            "x": -6,
            "y": 2,
            "z": 11,
            "elements": [
                "minecraft:nether_brick@0"
            ]
        },
        {
            "x": -7,
            "y": -2,
            "z": 9,
            "elements": [
                "contenttweaker:invar_casing@0"
            ]
        },
        {
            "x": -5,
            "y": 2,
            "z": 11,
            "elements": [
                "minecraft:purpur_block@0"
            ]
        },
        {
            "x": -3,
            "y": 6,
            "z": 13,
            "elements": [
                "minecraft:nether_brick_stairs@7"
            ]
        },
        {
            "x": -6,
            "y": -2,
            "z": 9,
            "elements": [
                "contenttweaker:invar_casing@0"
            ]
        },
        {
            "x": -5,
            "y": -2,
            "z": 9,
            "elements": [
                "minecraft:lava@0"
            ]
        },
        {
            "x": 0,
            "y": 6,
            "z": 13,
            "elements": [
                "minecraft:purpur_block@0"
            ]
        },
        {
            "x": -4,
            "y": -2,
            "z": 9,
            "elements": [
                "minecraft:lava@0"
            ]
        },
        {
            "x": -3,
            "y": -2,
            "z": 9,
            "elements": [
                "minecraft:lava@0"
            ]
        },
        {
            "x": -2,
            "y": -2,
            "z": 9,
            "elements": [
                "minecraft:lava@0"
            ]
        },
        {
            "x": 3,
            "y": 6,
            "z": 13,
            "elements": [
                "minecraft:nether_brick_stairs@7"
            ]
        },
        {
            "x": -1,
            "y": -2,
            "z": 9,
            "elements": [
                "minecraft:lava@0"
            ]
        },
        {
            "x": 0,
            "y": -2,
            "z": 9,
            "elements": [
                "minecraft:lava@0"
            ]
        },
        {
            "x": 1,
            "y": -2,
            "z": 9,
            "elements": [
                "minecraft:lava@0"
            ]
        },
        {
            "x": 2,
            "y": -2,
            "z": 9,
            "elements": [
                "minecraft:lava@0"
            ]
        },
        {
            "x": 5,
            "y": 2,
            "z": 11,
            "elements": [
                "minecraft:purpur_block@0"
            ]
        },
        {
            "x": 3,
            "y": -2,
            "z": 9,
            "elements": [
                "minecraft:lava@0"
            ]
        },
        {
            "x": 6,
            "y": 2,
            "z": 11,
            "elements": [
                "minecraft:nether_brick@0"
            ]
        },
        {
            "x": 4,
            "y": -2,
            "z": 9,
            "elements": [
                "minecraft:lava@0"
            ]
        },
        {
            "x": 7,
            "y": 2,
            "z": 11,
            "elements": [
                "minecraft:end_rod@1"
            ]
        },
        {
            "x": 5,
            "y": -2,
            "z": 9,
            "elements": [
                "minecraft:lava@0"
            ]
        },
        {
            "x": 6,
            "y": -2,
            "z": 9,
            "elements": [
                "contenttweaker:invar_casing@0"
            ]
        },
        {
            "x": 7,
            "y": -2,
            "z": 9,
            "elements": [
                "contenttweaker:invar_casing@0"
            ]
        },
        {
            "x": 8,
            "y": -2,
            "z": 9,
            "elements": [
                "contenttweaker:invar_casing@0"
            ]
        },
        {
            "x": -8,
            "y": -1,
            "z": 9,
            "elements": [
                "minecraft:purpur_block@0"
            ]
        },
        {
            "x": -6,
            "y": 3,
            "z": 11,
            "elements": [
                "minecraft:nether_brick_stairs@0"
            ]
        },
        {
            "x": -5,
            "y": 3,
            "z": 11,
            "elements": [
                "minecraft:nether_brick@0"
            ]
        },
        {
            "x": -4,
            "y": 3,
            "z": 11,
            "elements": [
                "minecraft:purpur_block@0"
            ]
        },
        {
            "x": 0,
            "y": 7,
            "z": 13,
            "elements": [
                "minecraft:purpur_block@0"
            ]
        },
        {
            "x": 4,
            "y": 3,
            "z": 11,
            "elements": [
                "minecraft:purpur_block@0"
            ]
        },
        {
            "x": 5,
            "y": 3,
            "z": 11,
            "elements": [
                "minecraft:nether_brick@0"
            ]
        },
        {
            "x": 6,
            "y": 3,
            "z": 11,
            "elements": [
                "minecraft:nether_brick_stairs@1"
            ]
        },
        {
            "x": 8,
            "y": -1,
            "z": 9,
            "elements": [
                "minecraft:purpur_block@0"
            ]
        },
        {
            "x": -8,
            "y": 0,
            "z": 9,
                        "elements": [
                "item_fluid_energy_in/output"
            ]
        },
        {
            "x": -5,
            "y": 4,
            "z": 11,
            "elements": [
                "minecraft:nether_brick@0"
            ]
        },
        {
            "x": -4,
            "y": 4,
            "z": 11,
            "elements": [
                "minecraft:purpur_block@0"
            ]
        },
        {
            "x": 0,
            "y": 8,
            "z": 13,
            "elements": [
                "minecraft:purpur_block@0"
            ]
        },
        {
            "x": 4,
            "y": 4,
            "z": 11,
            "elements": [
                "minecraft:purpur_block@0"
            ]
        },
        {
            "x": 5,
            "y": 4,
            "z": 11,
            "elements": [
                "minecraft:nether_brick@0"
            ]
        },
        {
            "x": 8,
            "y": 0,
            "z": 9,
                        "elements": [
                "item_fluid_energy_in/output"
            ]
        },
        {
            "x": -8,
            "y": 1,
            "z": 9,
            "elements": [
                "minecraft:iron_bars@0"
            ]
        },
        {
            "x": -5,
            "y": 5,
            "z": 11,
            "elements": [
                "minecraft:nether_brick@0"
            ]
        },
        {
            "x": -4,
            "y": 5,
            "z": 11,
            "elements": [
                "minecraft:purpur_block@0"
            ]
        },
        {
            "x": -3,
            "y": 5,
            "z": 11,
            "elements": [
                "minecraft:purpur_block@0"
            ]
        },
        {
            "x": 3,
            "y": 5,
            "z": 11,
            "elements": [
                "minecraft:purpur_block@0"
            ]
        },
        {
            "x": 4,
            "y": 5,
            "z": 11,
            "elements": [
                "minecraft:purpur_block@0"
            ]
        },
        {
            "x": 5,
            "y": 5,
            "z": 11,
            "elements": [
                "minecraft:nether_brick@0"
            ]
        },
        {
            "x": 8,
            "y": 1,
            "z": 9,
            "elements": [
                "minecraft:iron_bars@0"
            ]
        },
        {
            "x": -8,
            "y": 2,
            "z": 9,
            "elements": [
                "minecraft:iron_bars@0"
            ]
        },
        {
            "x": -5,
            "y": 6,
            "z": 11,
            "elements": [
                "minecraft:nether_brick_stairs@4"
            ]
        },
        {
            "x": -8,
            "y": -2,
            "z": 7,
            "elements": [
                "contenttweaker:invar_casing@0"
            ]
        },
        {
            "x": -4,
            "y": 6,
            "z": 11,
            "elements": [
                "minecraft:purpur_block@0"
            ]
        },
        {
            "x": -7,
            "y": -2,
            "z": 7,
            "elements": [
                "contenttweaker:invar_casing@0"
            ]
        },
        {
            "x": -3,
            "y": 6,
            "z": 11,
            "elements": [
                "minecraft:purpur_block@0"
            ]
        },
        {
            "x": -6,
            "y": -2,
            "z": 7,
            "elements": [
                "contenttweaker:invar_casing@0"
            ]
        },
        {
            "x": -2,
            "y": 6,
            "z": 11,
            "elements": [
                "minecraft:nether_brick_stairs@4"
            ]
        },
        {
            "x": -5,
            "y": -2,
            "z": 7,
            "elements": [
                "minecraft:lava@0"
            ]
        },
        {
            "x": 0,
            "y": 6,
            "z": 11,
            "elements": [
                "minecraft:red_nether_brick@0"
            ]
        },
        {
            "x": -4,
            "y": -2,
            "z": 7,
            "elements": [
                "minecraft:lava@0"
            ]
        },
        {
            "x": -3,
            "y": -2,
            "z": 7,
            "elements": [
                "minecraft:lava@0"
            ]
        },
        {
            "x": 2,
            "y": 6,
            "z": 11,
            "elements": [
                "minecraft:nether_brick_stairs@5"
            ]
        },
        {
            "x": -2,
            "y": -2,
            "z": 7,
            "elements": [
                "minecraft:lava@0"
            ]
        },
        {
            "x": 3,
            "y": 6,
            "z": 11,
            "elements": [
                "minecraft:purpur_block@0"
            ]
        },
        {
            "x": -1,
            "y": -2,
            "z": 7,
            "elements": [
                "minecraft:lava@0"
            ]
        },
        {
            "x": 0,
            "y": -2,
            "z": 7,
            "elements": [
                "minecraft:lava@0"
            ]
        },
        {
            "x": 4,
            "y": 6,
            "z": 11,
            "elements": [
                "minecraft:purpur_block@0"
            ]
        },
        {
            "x": 5,
            "y": 6,
            "z": 11,
            "elements": [
                "minecraft:nether_brick_stairs@5"
            ]
        },
        {
            "x": 1,
            "y": -2,
            "z": 7,
            "elements": [
                "minecraft:lava@0"
            ]
        },
        {
            "x": 2,
            "y": -2,
            "z": 7,
            "elements": [
                "minecraft:lava@0"
            ]
        },
        {
            "x": 3,
            "y": -2,
            "z": 7,
            "elements": [
                "minecraft:lava@0"
            ]
        },
        {
            "x": 4,
            "y": -2,
            "z": 7,
            "elements": [
                "minecraft:lava@0"
            ]
        },
        {
            "x": 5,
            "y": -2,
            "z": 7,
            "elements": [
                "minecraft:lava@0"
            ]
        },
        {
            "x": 8,
            "y": 2,
            "z": 9,
            "elements": [
                "minecraft:iron_bars@0"
            ]
        },
        {
            "x": 6,
            "y": -2,
            "z": 7,
            "elements": [
                "contenttweaker:invar_casing@0"
            ]
        },
        {
            "x": 7,
            "y": -2,
            "z": 7,
            "elements": [
                "contenttweaker:invar_casing@0"
            ]
        },
        {
            "x": 8,
            "y": -2,
            "z": 7,
            "elements": [
                "contenttweaker:invar_casing@0"
            ]
        },
        {
            "x": -9,
            "y": 3,
            "z": 9,
            "elements": [
                "minecraft:nether_brick_stairs@0"
            ]
        },
        {
            "x": -8,
            "y": 3,
            "z": 9,
            "elements": [
                "minecraft:purpur_block@0"
            ]
        },
        {
            "x": -7,
            "y": 3,
            "z": 9,
            "elements": [
                "minecraft:purpur_block@0"
            ]
        },
        {
            "x": -8,
            "y": -1,
            "z": 7,
            "elements": [
                "minecraft:purpur_block@0"
            ]
        },
        {
            "x": -6,
            "y": 3,
            "z": 9,
            "elements": [
                "minecraft:purpur_block@0"
            ]
        },
        {
            "x": -4,
            "y": 7,
            "z": 11,
            "elements": [
                "minecraft:purpur_block@0"
            ]
        },
        {
            "x": -5,
            "y": 3,
            "z": 9,
            "elements": [
                "minecraft:purpur_block@0"
            ]
        },
        {
            "x": -3,
            "y": 7,
            "z": 11,
            "elements": [
                "minecraft:purpur_block@0"
            ]
        },
        {
            "x": -2,
            "y": 7,
            "z": 11,
            "elements": [
                "minecraft:nether_brick_stairs@0"
            ]
        },
        {
            "x": 0,
            "y": 7,
            "z": 11,
            "elements": [
                "minecraft:red_nether_brick@0"
            ]
        },
        {
            "x": 2,
            "y": 7,
            "z": 11,
            "elements": [
                "minecraft:nether_brick_stairs@1"
            ]
        },
        {
            "x": 3,
            "y": 7,
            "z": 11,
            "elements": [
                "minecraft:purpur_block@0"
            ]
        },
        {
            "x": 4,
            "y": 7,
            "z": 11,
            "elements": [
                "minecraft:purpur_block@0"
            ]
        },
        {
            "x": 5,
            "y": 3,
            "z": 9,
            "elements": [
                "minecraft:purpur_block@0"
            ]
        },
        {
            "x": 6,
            "y": 3,
            "z": 9,
            "elements": [
                "minecraft:purpur_block@0"
            ]
        },
        {
            "x": 7,
            "y": 3,
            "z": 9,
            "elements": [
                "minecraft:purpur_block@0"
            ]
        },
        {
            "x": 8,
            "y": 3,
            "z": 9,
            "elements": [
                "minecraft:purpur_block@0"
            ]
        },
        {
            "x": 9,
            "y": 3,
            "z": 9,
            "elements": [
                "minecraft:nether_brick_stairs@1"
            ]
        },
        {
            "x": 8,
            "y": -1,
            "z": 7,
            "elements": [
                "minecraft:purpur_block@0"
            ]
        },
        {
            "x": -9,
            "y": 4,
            "z": 9,
            "elements": [
                "minecraft:nether_brick_stairs@4"
            ]
        },
        {
            "x": -8,
            "y": 4,
            "z": 9,
            "elements": [
                "minecraft:purpur_block@0"
            ]
        },
        {
            "x": -7,
            "y": 4,
            "z": 9,
            "elements": [
                "minecraft:purpur_block@0"
            ]
        },
        {
            "x": -8,
            "y": 0,
            "z": 7,
                        "elements": [
                "item_fluid_energy_in/output"
            ]
        },
        {
            "x": -6,
            "y": 4,
            "z": 9,
            "elements": [
                "minecraft:purpur_block@0"
            ]
        },
        {
            "x": -4,
            "y": 8,
            "z": 11,
            "elements": [
                "minecraft:purpur_stairs@4"
            ]
        },
        {
            "x": -5,
            "y": 4,
            "z": 9,
            "elements": [
                "minecraft:purpur_block@0"
            ]
        },
        {
            "x": -3,
            "y": 8,
            "z": 11,
            "elements": [
                "minecraft:purpur_block@0"
            ]
        },
        {
            "x": -2,
            "y": 8,
            "z": 11,
            "elements": [
                "minecraft:nether_brick_stairs@4"
            ]
        },
        {
            "x": -1,
            "y": 8,
            "z": 11,
            "elements": [
                "minecraft:purpur_block@0"
            ]
        },
        {
            "x": 0,
            "y": 8,
            "z": 11,
            "elements": [
                "minecraft:purpur_block@0"
            ]
        },
        {
            "x": 1,
            "y": 8,
            "z": 11,
            "elements": [
                "minecraft:purpur_block@0"
            ]
        },
        {
            "x": 2,
            "y": 8,
            "z": 11,
            "elements": [
                "minecraft:nether_brick_stairs@5"
            ]
        },
        {
            "x": 3,
            "y": 8,
            "z": 11,
            "elements": [
                "minecraft:purpur_block@0"
            ]
        },
        {
            "x": 4,
            "y": 8,
            "z": 11,
            "elements": [
                "minecraft:purpur_block@0"
            ]
        },
        {
            "x": 5,
            "y": 4,
            "z": 9,
            "elements": [
                "minecraft:purpur_block@0"
            ]
        },
        {
            "x": 6,
            "y": 4,
            "z": 9,
            "elements": [
                "minecraft:purpur_block@0"
            ]
        },
        {
            "x": 7,
            "y": 4,
            "z": 9,
            "elements": [
                "minecraft:purpur_block@0"
            ]
        },
        {
            "x": 8,
            "y": 4,
            "z": 9,
            "elements": [
                "minecraft:purpur_block@0"
            ]
        },
        {
            "x": 9,
            "y": 4,
            "z": 9,
            "elements": [
                "minecraft:nether_brick_stairs@5"
            ]
        },
        {
            "x": 8,
            "y": 0,
            "z": 7,
                        "elements": [
                "item_fluid_energy_in/output"
            ]
        },
        {
            "x": -9,
            "y": 5,
            "z": 9,
            "elements": [
                "minecraft:nether_brick_stairs@3"
            ]
        },
        {
            "x": -8,
            "y": 5,
            "z": 9,
            "elements": [
                "minecraft:purpur_block@0"
            ]
        },
        {
            "x": -7,
            "y": 5,
            "z": 9,
            "elements": [
                "minecraft:purpur_block@0"
            ]
        },
        {
            "x": -8,
            "y": 1,
            "z": 7,
            "elements": [
                "minecraft:iron_bars@0"
            ]
        },
        {
            "x": -6,
            "y": 5,
            "z": 9,
            "elements": [
                "minecraft:purpur_block@0"
            ]
        },
        {
            "x": -5,
            "y": 5,
            "z": 9,
            "elements": [
                "minecraft:purpur_block@0"
            ]
        },
        {
            "x": -1,
            "y": 9,
            "z": 11,
            "elements": [
                "minecraft:nether_brick_stairs@0"
            ]
        },
        {
            "x": 0,
            "y": 9,
            "z": 11,
            "elements": [
                "minecraft:nether_brick@0"
            ]
        },
        {
            "x": 1,
            "y": 9,
            "z": 11,
            "elements": [
                "minecraft:nether_brick_stairs@1"
            ]
        },
        {
            "x": 5,
            "y": 5,
            "z": 9,
            "elements": [
                "minecraft:purpur_block@0"
            ]
        },
        {
            "x": 6,
            "y": 5,
            "z": 9,
            "elements": [
                "minecraft:purpur_block@0"
            ]
        },
        {
            "x": 7,
            "y": 5,
            "z": 9,
            "elements": [
                "minecraft:purpur_block@0"
            ]
        },
        {
            "x": 8,
            "y": 5,
            "z": 9,
            "elements": [
                "minecraft:purpur_block@0"
            ]
        },
        {
            "x": 9,
            "y": 5,
            "z": 9,
            "elements": [
                "minecraft:nether_brick_stairs@3"
            ]
        },
        {
            "x": 8,
            "y": 1,
            "z": 7,
            "elements": [
                "minecraft:iron_bars@0"
            ]
        },
        {
            "x": -8,
            "y": 6,
            "z": 9,
            "elements": [
                "thaumcraft:stone_eldritch_tile@0"
            ]
        },
        {
            "x": -7,
            "y": 6,
            "z": 9,
            "elements": [
                "minecraft:purpur_block@0"
            ]
        },
        {
            "x": -8,
            "y": 2,
            "z": 7,
            "elements": [
                "minecraft:iron_bars@0"
            ]
        },
        {
            "x": -6,
            "y": 6,
            "z": 9,
            "elements": [
                "thaumcraft:stone_eldritch_tile@0"
            ]
        },
        {
            "x": -8,
            "y": -2,
            "z": 5,
            "elements": [
                "contenttweaker:invar_casing@0"
            ]
        },
        {
            "x": -4,
            "y": 6,
            "z": 9,
            "elements": [
                "minecraft:purpur_block@0"
            ]
        },
        {
            "x": 0,
            "y": 10,
            "z": 11,
            "elements": [
                "minecraft:nether_brick@0"
            ]
        },
        {
            "x": -6,
            "y": -2,
            "z": 5,
            "elements": [
                "minecraft:purpur_block@0"
            ]
        },
        {
            "x": -5,
            "y": -2,
            "z": 5,
            "elements": [
                "contenttweaker:bronze_firebox_casing@0"
            ]
        },
        {
            "x": -4,
            "y": -2,
            "z": 5,
            "elements": [
                "contenttweaker:invar_casing@0"
            ]
        },
        {
            "x": -3,
            "y": -2,
            "z": 5,
            "elements": [
                "minecraft:lava@0"
            ]
        },
        {
            "x": -2,
            "y": -2,
            "z": 5,
            "elements": [
                "minecraft:lava@0"
            ]
        },
        {
            "x": -1,
            "y": -2,
            "z": 5,
            "elements": [
                "minecraft:lava@0"
            ]
        },
        {
            "x": 0,
            "y": -2,
            "z": 5,
            "elements": [
                "minecraft:lava@0"
            ]
        },
        {
            "x": 4,
            "y": 6,
            "z": 9,
            "elements": [
                "minecraft:purpur_block@0"
            ]
        },
        {
            "x": 1,
            "y": -2,
            "z": 5,
            "elements": [
                "minecraft:lava@0"
            ]
        },
        {
            "x": 6,
            "y": 6,
            "z": 9,
            "elements": [
                "thaumcraft:stone_eldritch_tile@0"
            ]
        },
        {
            "x": 2,
            "y": -2,
            "z": 5,
            "elements": [
                "minecraft:lava@0"
            ]
        },
        {
            "x": 7,
            "y": 6,
            "z": 9,
            "elements": [
                "minecraft:purpur_block@0"
            ]
        },
        {
            "x": 3,
            "y": -2,
            "z": 5,
            "elements": [
                "minecraft:lava@0"
            ]
        },
        {
            "x": 8,
            "y": 6,
            "z": 9,
            "elements": [
                "thaumcraft:stone_eldritch_tile@0"
            ]
        },
        {
            "x": 4,
            "y": -2,
            "z": 5,
            "elements": [
                "contenttweaker:invar_casing@0"
            ]
        },
        {
            "x": 5,
            "y": -2,
            "z": 5,
            "elements": [
                "contenttweaker:bronze_firebox_casing@0"
            ]
        },
        {
            "x": 8,
            "y": 2,
            "z": 7,
            "elements": [
                "minecraft:iron_bars@0"
            ]
        },
        {
            "x": 6,
            "y": -2,
            "z": 5,
            "elements": [
                "minecraft:purpur_block@0"
            ]
        },
        {
            "x": 8,
            "y": -2,
            "z": 5,
            "elements": [
                "contenttweaker:invar_casing@0"
            ]
        },
        {
            "x": -8,
            "y": 7,
            "z": 9,
            "elements": [
                "iceandfire:dragon_bone_wall@0"
            ]
        },
        {
            "x": -9,
            "y": 3,
            "z": 7,
            "elements": [
                "minecraft:nether_brick_stairs@0"
            ]
        },
        {
            "x": -7,
            "y": 7,
            "z": 9,
            "elements": [
                "minecraft:purpur_block@0"
            ]
        },
        {
            "x": -8,
            "y": 3,
            "z": 7,
            "elements": [
                "minecraft:purpur_block@0"
            ]
        },
        {
            "x": -6,
            "y": 7,
            "z": 9,
            "elements": [
                "iceandfire:dragon_bone_wall@0"
            ]
        },
        {
            "x": -7,
            "y": 3,
            "z": 7,
            "elements": [
                "minecraft:purpur_block@0"
            ]
        },
        {
            "x": -8,
            "y": -1,
            "z": 5,
            "elements": [
                "thaumcraft:stone_eldritch_tile@0"
            ]
        },
        {
            "x": -6,
            "y": 3,
            "z": 7,
            "elements": [
                "minecraft:purpur_block@0"
            ]
        },
        {
            "x": -4,
            "y": 7,
            "z": 9,
            "elements": [
                "minecraft:purpur_block@0"
            ]
        },
        {
            "x": -7,
            "y": -1,
            "z": 5,
            "elements": [
                "thaumcraft:stone_eldritch_tile@0"
            ]
        },
        {
            "x": -5,
            "y": 3,
            "z": 7,
            "elements": [
                "minecraft:purpur_block@0"
            ]
        },
        {
            "x": 0,
            "y": 11,
            "z": 11,
            "elements": [
                "minecraft:nether_brick@0"
            ]
        },
        {
            "x": -6,
            "y": -1,
            "z": 5,
            "elements": [
                "minecraft:purpur_block@0"
            ]
        },
        {
            "x": 4,
            "y": 7,
            "z": 9,
            "elements": [
                "minecraft:purpur_block@0"
            ]
        },
        {
            "x": 6,
            "y": 7,
            "z": 9,
            "elements": [
                "iceandfire:dragon_bone_wall@0"
            ]
        },
        {
            "x": 7,
            "y": 7,
            "z": 9,
            "elements": [
                "minecraft:purpur_block@0"
            ]
        },
        {
            "x": 5,
            "y": 3,
            "z": 7,
            "elements": [
                "minecraft:purpur_block@0"
            ]
        },
        {
            "x": 8,
            "y": 7,
            "z": 9,
            "elements": [
                "iceandfire:dragon_bone_wall@0"
            ]
        },
        {
            "x": 6,
            "y": 3,
            "z": 7,
            "elements": [
                "minecraft:purpur_block@0"
            ]
        },
        {
            "x": 7,
            "y": 3,
            "z": 7,
            "elements": [
                "minecraft:purpur_block@0"
            ]
        },
        {
            "x": 8,
            "y": 3,
            "z": 7,
            "elements": [
                "minecraft:purpur_block@0"
            ]
        },
        {
            "x": 6,
            "y": -1,
            "z": 5,
            "elements": [
                "minecraft:purpur_block@0"
            ]
        },
        {
            "x": 9,
            "y": 3,
            "z": 7,
            "elements": [
                "minecraft:nether_brick_stairs@1"
            ]
        },
        {
            "x": 7,
            "y": -1,
            "z": 5,
            "elements": [
                "thaumcraft:stone_eldritch_tile@0"
            ]
        },
        {
            "x": 8,
            "y": -1,
            "z": 5,
            "elements": [
                "thaumcraft:stone_eldritch_tile@0"
            ]
        },
        {
            "x": -8,
            "y": 8,
            "z": 9,
            "elements": [
                "minecraft:end_rod@1"
            ]
        },
        {
            "x": -9,
            "y": 4,
            "z": 7,
            "elements": [
                "minecraft:nether_brick_stairs@4"
            ]
        },
        {
            "x": -7,
            "y": 8,
            "z": 9,
            "elements": [
                "minecraft:purpur_block@0"
            ]
        },
        {
            "x": -8,
            "y": 4,
            "z": 7,
            "elements": [
                "minecraft:purpur_block@0"
            ]
        },
        {
            "x": -6,
            "y": 8,
            "z": 9,
            "elements": [
                "minecraft:end_rod@1"
            ]
        },
        {
            "x": -7,
            "y": 4,
            "z": 7,
            "elements": [
                "minecraft:purpur_block@0"
            ]
        },
        {
            "x": -8,
            "y": 0,
            "z": 5,
            "elements": [
                "iceandfire:dragon_bone_wall@0"
            ]
        },
        {
            "x": -6,
            "y": 4,
            "z": 7,
            "elements": [
                "minecraft:purpur_block@0"
            ]
        },
        {
            "x": -7,
            "y": 0,
            "z": 5,
            "elements": [
                "thaumcraft:stone_eldritch_tile@0"
            ]
        },
        {
            "x": -5,
            "y": 4,
            "z": 7,
            "elements": [
                "minecraft:purpur_block@0"
            ]
        },
        {
            "x": -3,
            "y": 8,
            "z": 9,
            "elements": [
                "minecraft:purpur_block@0"
            ]
        },
        {
            "x": 0,
            "y": 12,
            "z": 11,
            "elements": [
                "minecraft:nether_brick@0"
            ]
        },
        {
            "x": -6,
            "y": 0,
            "z": 5,
            "elements": [
                "minecraft:purpur_block@0"
            ]
        },
        {
            "x": 3,
            "y": 8,
            "z": 9,
            "elements": [
                "minecraft:purpur_block@0"
            ]
        },
        {
            "x": 6,
            "y": 8,
            "z": 9,
            "elements": [
                "minecraft:end_rod@1"
            ]
        },
        {
            "x": 0,
            "y": 8,
            "z": -1,
            "elements": [
                "minecraft:nether_brick_stairs@3"
            ]
        },
        {
            "x": 7,
            "y": 8,
            "z": 9,
            "elements": [
                "minecraft:purpur_block@0"
            ]
        },
        {
            "x": 5,
            "y": 4,
            "z": 7,
            "elements": [
                "minecraft:purpur_block@0"
            ]
        },
        {
            "x": 8,
            "y": 8,
            "z": 9,
            "elements": [
                "minecraft:end_rod@1"
            ]
        },
        {
            "x": 6,
            "y": 4,
            "z": 7,
            "elements": [
                "minecraft:purpur_block@0"
            ]
        },
        {
            "x": 7,
            "y": 4,
            "z": 7,
            "elements": [
                "minecraft:purpur_block@0"
            ]
        },
        {
            "x": 8,
            "y": 4,
            "z": 7,
            "elements": [
                "minecraft:purpur_block@0"
            ]
        },
        {
            "x": 6,
            "y": 0,
            "z": 5,
            "elements": [
                "minecraft:purpur_block@0"
            ]
        },
        {
            "x": 9,
            "y": 4,
            "z": 7,
            "elements": [
                "minecraft:nether_brick_stairs@5"
            ]
        },
        {
            "x": 7,
            "y": 0,
            "z": 5,
            "elements": [
                "thaumcraft:stone_eldritch_tile@0"
            ]
        },
        {
            "x": 8,
            "y": 0,
            "z": 5,
            "elements": [
                "iceandfire:dragon_bone_wall@0"
            ]
        },
        {
            "x": -9,
            "y": 5,
            "z": 7,
            "elements": [
                "minecraft:nether_brick_stairs@2"
            ]
        },
        {
            "x": -8,
            "y": 5,
            "z": 7,
            "elements": [
                "minecraft:purpur_block@0"
            ]
        },
        {
            "x": -7,
            "y": 5,
            "z": 7,
            "elements": [
                "minecraft:purpur_block@0"
            ]
        },
        {
            "x": -8,
            "y": 1,
            "z": 5,
            "elements": [
                "minecraft:end_rod@1"
            ]
        },
        {
            "x": -6,
            "y": 5,
            "z": 7,
            "elements": [
                "minecraft:purpur_block@0"
            ]
        },
        {
            "x": -7,
            "y": 1,
            "z": 5,
            "elements": [
                "iceandfire:dragon_bone_wall@0"
            ]
        },
        {
            "x": -5,
            "y": 5,
            "z": 7,
            "elements": [
                "minecraft:purpur_block@0"
            ]
        },
        {
            "x": -3,
            "y": 9,
            "z": 9,
            "elements": [
                "minecraft:nether_brick_stairs@3"
            ]
        },
        {
            "x": 0,
            "y": 13,
            "z": 11,
            "elements": [
                "minecraft:stone_slab@6"
            ]
        },
        {
            "x": -6,
            "y": 1,
            "z": 5,
            "elements": [
                "minecraft:purpur_block@0"
            ]
        },
        {
            "x": -2,
            "y": 9,
            "z": 9,
            "elements": [
                "minecraft:purpur_block@0"
            ]
        },
        {
            "x": -1,
            "y": 9,
            "z": 9,
            "elements": [
                "minecraft:red_nether_brick@0"
            ]
        },
        {
            "x": 1,
            "y": 9,
            "z": 9,
            "elements": [
                "minecraft:red_nether_brick@0"
            ]
        },
        {
            "x": 2,
            "y": 9,
            "z": 9,
            "elements": [
                "minecraft:purpur_block@0"
            ]
        },
        {
            "x": 3,
            "y": 9,
            "z": 9,
            "elements": [
                "minecraft:nether_brick_stairs@3"
            ]
        },
        {
            "x": 0,
            "y": 7,
            "z": -1,
            "elements": [
                "minecraft:nether_brick_stairs@6"
            ]
        },
        {
            "x": 5,
            "y": 5,
            "z": 7,
            "elements": [
                "minecraft:purpur_block@0"
            ]
        },
        {
            "x": 6,
            "y": 5,
            "z": 7,
            "elements": [
                "minecraft:purpur_block@0"
            ]
        },
        {
            "x": 7,
            "y": 5,
            "z": 7,
            "elements": [
                "minecraft:purpur_block@0"
            ]
        },
        {
            "x": 8,
            "y": 5,
            "z": 7,
            "elements": [
                "minecraft:purpur_block@0"
            ]
        },
        {
            "x": 6,
            "y": 1,
            "z": 5,
            "elements": [
                "minecraft:purpur_block@0"
            ]
        },
        {
            "x": 9,
            "y": 5,
            "z": 7,
            "elements": [
                "minecraft:nether_brick_stairs@2"
            ]
        },
        {
            "x": 7,
            "y": 1,
            "z": 5,
            "elements": [
                "iceandfire:dragon_bone_wall@0"
            ]
        },
        {
            "x": 8,
            "y": 1,
            "z": 5,
            "elements": [
                "minecraft:end_rod@1"
            ]
        },
        {
            "x": -8,
            "y": 6,
            "z": 7,
            "elements": [
                "thaumcraft:stone_eldritch_tile@0"
            ]
        },
        {
            "x": -7,
            "y": 6,
            "z": 7,
            "elements": [
                "minecraft:purpur_block@0"
            ]
        },
        {
            "x": -6,
            "y": 6,
            "z": 7,
            "elements": [
                "thaumcraft:stone_eldritch_tile@0"
            ]
        },
        {
            "x": -7,
            "y": 2,
            "z": 5,
            "elements": [
                "minecraft:end_rod@1"
            ]
        },
        {
            "x": -6,
            "y": 2,
            "z": 5,
            "elements": [
                "minecraft:nether_brick@0"
            ]
        },
        {
            "x": -4,
            "y": 6,
            "z": 7,
            "elements": [
                "minecraft:purpur_block@0"
            ]
        },
        {
            "x": -7,
            "y": -2,
            "z": 3,
            "elements": [
                "contenttweaker:invar_casing@0"
            ]
        },
        {
            "x": -5,
            "y": 2,
            "z": 5,
            "elements": [
                "minecraft:purpur_block@0"
            ]
        },
        {
            "x": -5,
            "y": -2,
            "z": 3,
            "elements": [
                "minecraft:purpur_block@0"
            ]
        },
        {
            "x": -4,
            "y": -2,
            "z": 3,
            "elements": [
                "minecraft:lava@0"
            ]
        },
        {
            "x": -3,
            "y": -2,
            "z": 3,
            "elements": [
                "contenttweaker:bronze_firebox_casing@0"
            ]
        },
        {
            "x": -2,
            "y": -2,
            "z": 3,
            "elements": [
                "contenttweaker:invar_casing@0"
            ]
        },
        {
            "x": -1,
            "y": -2,
            "z": 3,
            "elements": [
                "minecraft:lava@0"
            ]
        },
        {
            "x": 0,
            "y": -2,
            "z": 3,
            "elements": [
                "minecraft:lava@0"
            ]
        },
        {
            "x": 4,
            "y": 6,
            "z": 7,
            "elements": [
                "minecraft:purpur_block@0"
            ]
        },
        {
            "x": 0,
            "y": 6,
            "z": -1,
            "elements": [
                "minecraft:nether_brick_stairs@2"
            ]
        },
        {
            "x": 1,
            "y": -2,
            "z": 3,
            "elements": [
                "minecraft:lava@0"
            ]
        },
        {
            "x": 6,
            "y": 6,
            "z": 7,
            "elements": [
                "thaumcraft:stone_eldritch_tile@0"
            ]
        },
        {
            "x": 2,
            "y": -2,
            "z": 3,
            "elements": [
                "contenttweaker:invar_casing@0"
            ]
        },
        {
            "x": 7,
            "y": 6,
            "z": 7,
            "elements": [
                "minecraft:purpur_block@0"
            ]
        },
        {
            "x": 5,
            "y": 2,
            "z": 5,
            "elements": [
                "minecraft:purpur_block@0"
            ]
        },
        {
            "x": 3,
            "y": -2,
            "z": 3,
            "elements": [
                "contenttweaker:bronze_firebox_casing@0"
            ]
        },
        {
            "x": 8,
            "y": 6,
            "z": 7,
            "elements": [
                "thaumcraft:stone_eldritch_tile@0"
            ]
        },
        {
            "x": 6,
            "y": 2,
            "z": 5,
            "elements": [
                "minecraft:nether_brick@0"
            ]
        },
        {
            "x": 4,
            "y": -2,
            "z": 3,
            "elements": [
                "minecraft:lava@0"
            ]
        },
        {
            "x": 7,
            "y": 2,
            "z": 5,
            "elements": [
                "minecraft:end_rod@1"
            ]
        },
        {
            "x": 5,
            "y": -2,
            "z": 3,
            "elements": [
                "minecraft:purpur_block@0"
            ]
        },
        {
            "x": 7,
            "y": -2,
            "z": 3,
            "elements": [
                "contenttweaker:invar_casing@0"
            ]
        },
        {
            "x": -8,
            "y": 7,
            "z": 7,
            "elements": [
                "iceandfire:dragon_bone_wall@0"
            ]
        },
        {
            "x": -7,
            "y": 7,
            "z": 7,
            "elements": [
                "minecraft:purpur_block@0"
            ]
        },
        {
            "x": -6,
            "y": 7,
            "z": 7,
            "elements": [
                "iceandfire:dragon_bone_wall@0"
            ]
        },
        {
            "x": -6,
            "y": 3,
            "z": 5,
            "elements": [
                "minecraft:nether_brick_stairs@0"
            ]
        },
        {
            "x": -4,
            "y": 7,
            "z": 7,
            "elements": [
                "minecraft:purpur_block@0"
            ]
        },
        {
            "x": -7,
            "y": -1,
            "z": 3,
            "elements": [
                "thaumcraft:stone_eldritch_tile@0"
            ]
        },
        {
            "x": -5,
            "y": 3,
            "z": 5,
            "elements": [
                "minecraft:nether_brick@0"
            ]
        },
        {
            "x": -6,
            "y": -1,
            "z": 3,
            "elements": [
                "thaumcraft:stone_eldritch_tile@0"
            ]
        },
        {
            "x": -4,
            "y": 3,
            "z": 5,
            "elements": [
                "minecraft:purpur_block@0"
            ]
        },
        {
            "x": -5,
            "y": -1,
            "z": 3,
            "elements": [
                "minecraft:purpur_block@0"
            ]
        },
        {
            "x": 1,
            "y": 5,
            "z": -1,
            "elements": [
                "minecraft:nether_brick_stairs@1"
            ]
        },
        {
            "x": 4,
            "y": 7,
            "z": 7,
            "elements": [
                "minecraft:purpur_block@0"
            ]
        },
        {
            "x": -1,
            "y": 5,
            "z": -1,
            "elements": [
                "minecraft:nether_brick_stairs@0"
            ]
        },
        {
            "x": 6,
            "y": 7,
            "z": 7,
            "elements": [
                "iceandfire:dragon_bone_wall@0"
            ]
        },
        {
            "x": 4,
            "y": 3,
            "z": 5,
            "elements": [
                "minecraft:purpur_block@0"
            ]
        },
        {
            "x": 7,
            "y": 7,
            "z": 7,
            "elements": [
                "minecraft:purpur_block@0"
            ]
        },
        {
            "x": 5,
            "y": 3,
            "z": 5,
            "elements": [
                "minecraft:nether_brick@0"
            ]
        },
        {
            "x": 8,
            "y": 7,
            "z": 7,
            "elements": [
                "iceandfire:dragon_bone_wall@0"
            ]
        },
        {
            "x": 6,
            "y": 3,
            "z": 5,
            "elements": [
                "minecraft:nether_brick_stairs@1"
            ]
        },
        {
            "x": 5,
            "y": -1,
            "z": 3,
            "elements": [
                "minecraft:purpur_block@0"
            ]
        },
        {
            "x": 6,
            "y": -1,
            "z": 3,
            "elements": [
                "thaumcraft:stone_eldritch_tile@0"
            ]
        },
        {
            "x": 7,
            "y": -1,
            "z": 3,
            "elements": [
                "thaumcraft:stone_eldritch_tile@0"
            ]
        },
        {
            "x": -8,
            "y": 8,
            "z": 7,
            "elements": [
                "minecraft:end_rod@1"
            ]
        },
        {
            "x": -7,
            "y": 8,
            "z": 7,
            "elements": [
                "minecraft:purpur_block@0"
            ]
        },
        {
            "x": -6,
            "y": 8,
            "z": 7,
            "elements": [
                "minecraft:end_rod@1"
            ]
        },
        {
            "x": -2,
            "y": 12,
            "z": 9,
            "elements": [
                "minecraft:nether_brick@0"
            ]
        },
        {
            "x": -7,
            "y": 0,
            "z": 3,
            "elements": [
                "iceandfire:dragon_bone_wall@0"
            ]
        },
        {
            "x": -5,
            "y": 4,
            "z": 5,
            "elements": [
                "minecraft:nether_brick@0"
            ]
        },
        {
            "x": -3,
            "y": 8,
            "z": 7,
            "elements": [
                "minecraft:purpur_block@0"
            ]
        },
        {
            "x": -6,
            "y": 0,
            "z": 3,
            "elements": [
                "thaumcraft:stone_eldritch_tile@0"
            ]
        },
        {
            "x": -4,
            "y": 4,
            "z": 5,
            "elements": [
                "minecraft:purpur_block@0"
            ]
        },
        {
            "x": -5,
            "y": 0,
            "z": 3,
            "elements": [
                "minecraft:purpur_block@0"
            ]
        },
        {
            "x": 2,
            "y": 12,
            "z": 9,
            "elements": [
                "minecraft:nether_brick@0"
            ]
        },
        {
            "x": 3,
            "y": 8,
            "z": 7,
            "elements": [
                "minecraft:purpur_block@0"
            ]
        },
        {
            "x": 1,
            "y": 4,
            "z": -1,
            "elements": [
                "minecraft:nether_brick_stairs@6"
            ]
        },
        {
            "x": -1,
            "y": 4,
            "z": -1,
            "elements": [
                "minecraft:nether_brick_stairs@6"
            ]
        },
        {
            "x": 6,
            "y": 8,
            "z": 7,
            "elements": [
                "minecraft:end_rod@1"
            ]
        },
        {
            "x": 4,
            "y": 4,
            "z": 5,
            "elements": [
                "minecraft:purpur_block@0"
            ]
        },
        {
            "x": 7,
            "y": 8,
            "z": 7,
            "elements": [
                "minecraft:purpur_block@0"
            ]
        },
        {
            "x": 5,
            "y": 4,
            "z": 5,
            "elements": [
                "minecraft:nether_brick@0"
            ]
        },
        {
            "x": 8,
            "y": 8,
            "z": 7,
            "elements": [
                "minecraft:end_rod@1"
            ]
        },
        {
            "x": 5,
            "y": 0,
            "z": 3,
            "elements": [
                "minecraft:purpur_block@0"
            ]
        },
        {
            "x": 6,
            "y": 0,
            "z": 3,
            "elements": [
                "thaumcraft:stone_eldritch_tile@0"
            ]
        },
        {
            "x": 7,
            "y": 0,
            "z": 3,
            "elements": [
                "iceandfire:dragon_bone_wall@0"
            ]
        },
        {
            "x": -2,
            "y": 13,
            "z": 9,
            "elements": [
                "minecraft:stone_slab@6"
            ]
        },
        {
            "x": -7,
            "y": 1,
            "z": 3,
            "elements": [
                "minecraft:end_rod@1"
            ]
        },
        {
            "x": -5,
            "y": 5,
            "z": 5,
            "elements": [
                "minecraft:nether_brick@0"
            ]
        },
        {
            "x": -3,
            "y": 9,
            "z": 7,
            "elements": [
                "minecraft:nether_brick_stairs@2"
            ]
        },
        {
            "x": -1,
            "y": 13,
            "z": 9,
            "elements": [
                "minecraft:nether_brick@0"
            ]
        },
        {
            "x": -6,
            "y": 1,
            "z": 3,
            "elements": [
                "iceandfire:dragon_bone_wall@0"
            ]
        },
        {
            "x": -4,
            "y": 5,
            "z": 5,
            "elements": [
                "minecraft:purpur_block@0"
            ]
        },
        {
            "x": -2,
            "y": 9,
            "z": 7,
            "elements": [
                "minecraft:purpur_block@0"
            ]
        },
        {
            "x": -5,
            "y": 1,
            "z": 3,
            "elements": [
                "minecraft:purpur_block@0"
            ]
        },
        {
            "x": -3,
            "y": 5,
            "z": 5,
            "elements": [
                "minecraft:purpur_block@0"
            ]
        },
        {
            "x": -1,
            "y": 9,
            "z": 7,
            "elements": [
                "minecraft:red_nether_brick@0"
            ]
        },
        {
            "x": 1,
            "y": 13,
            "z": 9,
            "elements": [
                "minecraft:nether_brick@0"
            ]
        },
        {
            "x": 2,
            "y": 13,
            "z": 9,
            "elements": [
                "minecraft:stone_slab@6"
            ]
        },
        {
            "x": -4,
            "y": 1,
            "z": 3,
            "elements": [
                "minecraft:purpur_block@0"
            ]
        },
        {
            "x": 1,
            "y": 9,
            "z": 7,
            "elements": [
                "minecraft:red_nether_brick@0"
            ]
        },
        {
            "x": 2,
            "y": 9,
            "z": 7,
            "elements": [
                "minecraft:purpur_block@0"
            ]
        },
        {
            "x": 3,
            "y": 9,
            "z": 7,
            "elements": [
                "minecraft:nether_brick_stairs@2"
            ]
        },
        {
            "x": 1,
            "y": 3,
            "z": -1,
            "elements": [
                "minecraft:nether_brick_stairs@2"
            ]
        },
        {
            "x": 3,
            "y": 5,
            "z": 5,
            "elements": [
                "minecraft:purpur_block@0"
            ]
        },
        {
            "x": -1,
            "y": 3,
            "z": -1,
            "elements": [
                "minecraft:nether_brick_stairs@2"
            ]
        },
        {
            "x": 4,
            "y": 5,
            "z": 5,
            "elements": [
                "minecraft:purpur_block@0"
            ]
        },
        {
            "x": 5,
            "y": 5,
            "z": 5,
            "elements": [
                "minecraft:nether_brick@0"
            ]
        },
        {
            "x": 4,
            "y": 1,
            "z": 3,
            "elements": [
                "minecraft:purpur_block@0"
            ]
        },
        {
            "x": 5,
            "y": 1,
            "z": 3,
            "elements": [
                "minecraft:purpur_block@0"
            ]
        },
        {
            "x": 6,
            "y": 1,
            "z": 3,
            "elements": [
                "iceandfire:dragon_bone_wall@0"
            ]
        },
        {
            "x": 7,
            "y": 1,
            "z": 3,
            "elements": [
                "minecraft:end_rod@1"
            ]
        },
        {
            "x": -5,
            "y": 6,
            "z": 5,
            "elements": [
                "minecraft:nether_brick_stairs@4"
            ]
        },
        {
            "x": -1,
            "y": 14,
            "z": 9,
            "elements": [
                "minecraft:nether_brick@0"
            ]
        },
        {
            "x": -6,
            "y": 2,
            "z": 3,
            "elements": [
                "minecraft:end_rod@1"
            ]
        },
        {
            "x": -4,
            "y": 6,
            "z": 5,
            "elements": [
                "minecraft:purpur_block@0"
            ]
        },
        {
            "x": -5,
            "y": 2,
            "z": 3,
            "elements": [
                "minecraft:iron_bars@0"
            ]
        },
        {
            "x": -3,
            "y": 6,
            "z": 5,
            "elements": [
                "minecraft:purpur_block@0"
            ]
        },
        {
            "x": 1,
            "y": 14,
            "z": 9,
            "elements": [
                "minecraft:nether_brick@0"
            ]
        },
        {
            "x": -6,
            "y": -2,
            "z": 1,
            "elements": [
                "contenttweaker:invar_casing@0"
            ]
        },
        {
            "x": -4,
            "y": 2,
            "z": 3,
            "elements": [
                "minecraft:iron_bars@0"
            ]
        },
        {
            "x": -2,
            "y": 6,
            "z": 5,
            "elements": [
                "minecraft:nether_brick_stairs@4"
            ]
        },
        {
            "x": -5,
            "y": -2,
            "z": 1,
            "elements": [
                "contenttweaker:invar_casing@0"
            ]
        },
        {
            "x": -3,
            "y": 2,
            "z": 3,
            "elements": [
                "minecraft:purpur_block@0"
            ]
        },
        {
            "x": 0,
            "y": 6,
            "z": 5,
            "elements": [
                "minecraft:red_nether_brick@0"
            ]
        },
        {
            "x": 2,
            "y": 2,
            "z": -1,
            "elements": [
                "minecraft:nether_brick_stairs@1"
            ]
        },
        {
            "x": 2,
            "y": 6,
            "z": 5,
            "elements": [
                "minecraft:nether_brick_stairs@5"
            ]
        },
        {
            "x": -2,
            "y": -2,
            "z": 1,
            "elements": [
                "contenttweaker:bronze_firebox_casing@0"
            ]
        },
        {
            "x": 3,
            "y": 6,
            "z": 5,
            "elements": [
                "minecraft:purpur_block@0"
            ]
        },
        {
            "x": -1,
            "y": -2,
            "z": 1,
            "elements": [
                "contenttweaker:invar_casing@0"
            ]
        },
        {
            "x": 0,
            "y": -2,
            "z": 1,
            "elements": [
                "contenttweaker:invar_casing@0"
            ]
        },
        {
            "x": 4,
            "y": 6,
            "z": 5,
